Workbook

Sheet 0_概要
A1: コンサルティング営業体験（60分版）設計書
A2: 大学生向け新卒採用プログラム。スライドは program60-slides.pptx（本編45枚＋補足6枚）
A4: シート | B4: 内容
A5: ①既存69枚の分析 | B5: 既存スライドごとに、残す・統合・移動・削除・変更の判断と、新しいスライド番号
A6: ②全体構成 | B6: 6フェーズのタイムライン、スライド構成、参加型ワークの配置
A7: ③改善後の本編スライド | B7: program60-slides.pptx（別ファイル）。各スライドのノートに講師用台本の要約
A8: ④講師用進行台本 | B8: スライドごとの説明・問いかけ・想定回答・フィードバック・ヒント・つなぎ・時間超過時の調整
A9: ⑤画像・動画差し替え管理 | B9: 差し替え枠の番号・配置・目的・枠の大きさと比率・仮素材・状況
A10: ⑥品質確認 | B10: 指示書20章の8項目のチェック結果
A11: ⑦アンケート | B11: 事前・事後の設問と、成果を見る指標
A12: ⑧要確認事項 | B12: 推測で埋めずに残した事項。だれに確認するか
A14: 黄色のセルは、運営側が記入する欄です（担当・差し替え日・状況など）。

Sheet 1_既存69枚の分析
A1: 成果物① 既存資料（69枚）の改善分析
A2: 判断：残す（改善）／統合／移動／削除／変更。移動先が「講師台本」のものは、画面から外して講師が使う
A4: 既存No | B4: 既存スライド | C4: 判断 | D4: 新しいスライド | E4: 理由・変えること
A5: 1 | B5: YOUR MISSION | C5: 残す（改善） | D5: S01・S03 | E5: ミッション感は強み。60分の流れと「正解より理由」のルールを足す
A6: 2 | B6: 佐藤さんの相談（課題発生） | C6: 統合 | D6: S04 | E6: 映像①と一体にし、直後に「何が気になる？」の問いを置く
A7: 3 | B7: 問い P1-Q1 | C7: 残す（改善） | D7: S06 | E7: 考える時間30秒と「選んだ理由」の確認を足す
A8: 4 | B8: 先輩のヒント P1-Q1 | C8: 移動 | D8: 講師台本（S06） | E8: 画面に出すと考える前に答えが見える。講師が迷った学生に出す
A9: 5 | B9: 分岐A センサを確認 | C9: 統合 | D9: S07 | E9: 3つの分岐を1枚で比べ、判断理由を解説する形に
A10: 6 | B10: 分岐B いつ・どれくらい | C10: 統合 | D10: S07 | E10: 同上（おすすめとして表示）
A11: 7 | B11: 分岐C 交換を提案 | C11: 統合 | D11: S07 | E11: 同上
A12: 8 | B12: 現状データ | C12: 残す（改善） | D12: S08 | E12: グラフで「毎週ではない」を一目で。演習用の設定値と明記
A13: 9 | B13: 問い P1-Q2 | C13: 残す（改善） | D13: S10 | E13: 考える時間と理由の確認を足す
A14: 10 | B14: 先輩のヒント P1-Q2 | C14: 移動 | D14: 講師台本（S10） | E14: 同上
A15: 11 | B15: 分岐A ラインを見る | C15: 統合 | D15: S11 | E15: 3つの分岐を1枚に
A16: 12 | B16: 分岐B 予算を聞く | C16: 統合 | D16: S11 | E16: 同上
... A25: 21 | B25: 問い P2-Q2 どう確かめる？ | C25: 残す | D25: S20 | E25: 考える時間と理由の確認を足す
A26: 22 | B26: 先輩のヒント P2-Q2 | C26: 移動 | D26: 講師台本（S20）
A27: 23 | B27: 分岐A すぐ交換 | C27: 統合 | D27: S21 | E27: お客様の反応は、提案の判断基準（S30）にも使う
A28: 24 | B28: 分岐B 同時に記録 | C28: 統合 | D28: S21 | E28: 切り分けの図にする
A29: 25 | B29: 分岐C 速度を下げる | C29: 統合 | D29: S21・S30 | E29: 「速度は落とせない」を顧客要求の根拠として再利用
A30: 26 | B30: 原因の候補を整理する | C30: 統合 | D30: S17・S22・S23 | E30: 「原因を決めつけずに調べるには？」のワークに発展
A31: 27 | B31: 本当の困りごとは？（何とか対応） | C31: 残す（改善） | D31: S25 | E31: この一言の裏を考えさせる問いを足す
A32: 28 | B32: 問い P3-Q1 | C32: 変更 | D32: S25 | E32: 3択→自由記述（何を聞くか）
A33: 29 | B33: 先輩のヒント P3-Q1 | C33: 移動 | D33: 講師台本（S25）
A34: 30 | B34: 確認の手間を聞く | C34: 統合 | D34: S26 | E34: 業務への影響の発見
A35: 31 | B35: 価格を聞く | C35: 統合 | D35: S26 | E35: 側面の比較として小さく
A36: 32 | B36: 他社の事例を聞く | C36: 統合 | D36: S26 | E36: 同上
A37: 33 | B37: 問い P3-Q2 本当の困りごと | C37: 変更 | D37: S27 | E37: 3択→自由記述ワーク「誤カウントがなくなると、何がうれしい？」
A38: 34 | B38: 先輩のヒント P3-Q2 | C38: 移動 | D38: 講師台本（S27）
A39: 35 | B39: 分岐A メーカーが原因？ | C39: 削除 | D39: 講師台本（S27の想定回答） | E39: 「他社製だから」という見方を画面に出さない。出たら講師が扱う
A40: 36 | B40: 分岐B 負担が本当の困りごと | C40: 統合 | D40: S28・S29 | E40: 3段構造。3段目を伏せて学生に言わせてから見せる
A41: 37 | B41: 分岐C 価格が課題？ | C41: 統合 | D41: S29 | E41: 佐藤さん「価格より安定」を答え合わせに使う
A42: 38 | B42: 見えてきた課題 | C42: 残す（強化） | D42: S30 | E42: 顧客要求＝提案の判断基準として整理し、提案パートにつなぐ
A43: 39 | B43: 解決提案へ | C43: 統合 | D43: S32 | E43: 提案の6ステップの中に置く
A44: 40 | B44: 問い P4-Q1 どう提案する？ | C44: 変更 | D44: S35 | E44: 3択→模擬提案ワーク（自分の言葉で）
A45: 41 | B45: 先輩のヒント P4-Q1 | C45: 統合 | D45: S35 | E45: 提案の型（穴埋め）として渡す
A46: 42 | B46: 分岐A 高性能センサへ交換 | C46: 移動 | D46: 講師台本（S36のフィードバック） | E46: よく出る提案として講師が扱う
A47: 43 | B47: 分岐B KR-Qで実ボトル検証 | C47: 移動 | D47: S37 | E47: 学生の発表のあとに、お客様の反応として見せる
A48: 44 | B48: 分岐C 人が再確認 | C48: 統合 | D48: S30 | E48: 「人の作業は増やしたくない」を顧客要求の根拠に
A49: 45 | B49: KR-Qシリーズの説明 | C49: 残す（改善） | D49: S33 | E49: 確認できた情報だけに絞る。「必ず直る」と言わない
...

Sheet 4_講師用進行台本
A1: 成果物④ 講師用進行台本
A2: 開始・終了は「所要（分）」から自動計算。所要を変えると全体の時間が更新される。黄色＝当日の担当メモ
A3: 薄い赤の行＝学生が手を動かす場面
A4: No | B4: フェーズ | C4: 開始 | D4: 所要（分） | E4: 終了 | F4: 進め方 | G4: 画面に表示する内容 | H4: 講師の説明・発話 | I4: 学生への問いかけ | J4: 想定される学生の回答 | K4: 回答へのフィードバック | L4: 答えが出ないときのヒント | M4: 使用する画像・動画 | N4: 次へのつなぎ | O4: 時間超過時の調整 | P4: 既存スライド | Q4: 当日メモ
A5: S01 | B5: MISSION | C5: =0 -> 0 | D5: 0.5 | E5: =C5+D5 -> 0.5 | F5: 講師 | G5: タイトル「YOUR MISSION ペットボトルの誤カウントを解決せよ。」 | H5: これから60分、皆さんにはOPTEX-FAの営業担当になってもらいます。センサの知識はいりません。必要なのは、お客様の話を聞いて、考えることだけです。 | M5: IMAGE_PLACEHOLDER_01（PETボトル搬送ライン） | N5: 始める前に、今の気持ちを教えてください。 | O5: 省略不可 | P5: 既存1
A6: S02 | B6: MISSION | C6: =E5 -> 0.5 | D6: 1 | E6: =C6+D6 -> 1.5 | F6: 個人 | G6: 事前チェック2問とQRコード | H6: 正解はありません。今の正直な気持ちを答えてください。最後にもう一度聞いて、変化を見ます。 | I6: 営業の仕事に、どれくらい興味がありますか？／営業とはどんな仕事だと思いますか？ | J6: 「商品を売る仕事」「ノルマがきつそう」「話がうまい人の仕事」 | K6: 答えにはコメントしない。「最後にもう一度聞きます」とだけ伝える。 | M6: IMAGE_PLACEHOLDER_09（事前チェックのQRコード） | N6: では、今日のミッションを説明します。 | O6: 時間がなければ紙で回収。省略すると前後比較ができなくなるため、原則実施 | P6: 新規
A7: S03 | B7: MISSION | C7: =E6 -> 1.5 | D7: 1 | E7: =C7+D7 -> 2.5 | F7: 講師 | G7: 6つのフェーズと、学生がすること（受け取る→選ぶ→考える→発見する→提案する→言葉にする） | H7: 今日は6つの段階で進みます。最初は選ぶだけ。だんだん自分で考える場面が増えて、最後は自分の言葉でお客様に提案してもらいます。 | N7: さっそく、お客様から相談が届きました。 | O7: 30秒に短縮可（ルールだけ読む） | P7: 既存1＋新規
A8: S04 | B8: MISSION | C8: =E7 -> 2.5 | D8: 2.5 | E8: =C8+D8 -> 5 | F8: 動画 | G8: 映像①（60秒以内）→ 佐藤さんの相談 → 問い | H8: （映像のあと）飲料工場の設備課、佐藤さんからの相談です。ボトルの本数を数える仕組みが、ときどき実際より多く数えてしまうそうです。 | I8: あなたなら、まず何が気になりますか？（近くの人と10秒） | J8: 「どれくらい多いの？」「機械が壊れている？」「いつから？」 | K8: 「いい疑問です。その疑問を、お客様への質問に変えていきましょう」と次につなぐ。 | L8: 「自分が工場の人だったら、何に困るか」を想像してみましょう。 | M8: VIDEO_PLACEHOLDER_01（映像① 課題発生） | N8: ここからHEARING。お客様に質問していきます。 | O8: 映像を60秒以内に収める。既存の導入動画（3分58秒）をそのまま流すと時間を超える | P8: 既存2＋導入動画
A9: S05 | B9: HEARING | C9: =E8 -> 5 | D9: 0.25 | E9: =C9+D9 -> 5.25 | F9: 講師 | G9: フェーズの扉 | H9: 最初は「聞く」です。営業の仕事は、話すことより聞くことから始まります。 | N9: 最初の質問を選んでください。 | O9: 読み上げずに次へ | P9: 新規
A10: S06 | B10: HEARING | C10: =E9 -> 5.25 | D10: 2 | E10: =C10+D10 -> 7.25 | F10: 個人→投票 | G10: 問いと3つの選択肢、考える時間30秒 | H10: 30秒考えて、1つ選んでください。選んだら、理由をひとことでメモしてください。 | I10: なぜ、それを選びましたか？（2〜3人に理由を聞く） | J10: A「どんな機械か分からないと始まらない」／B「どれくらい困っているか知りたい」／C「新しくすれば直りそう」 | K10: どれを選んでも理由を認める。Cの人には「早く解決したい気持ちは営業として大事」と認めてから、次の解説へ。 | L10: 森さん「専門知識がなくても大丈夫。お客様の困りごとを、もっと具体的にするには？」 | N10: それぞれ聞いてみると、お客様はこう答えました。 | O10: 理由の聞き取りを1人にすれば1分に短縮 | P10: 既存3・4
A11: S07 | B11: HEARING | C11: =E10 -> 7.25 | D11: 1.5 | E11: =C11+D11 -> 8.75 | F11: 講師 | G11: 3つの選択肢それぞれの、お客様の答えと分かったこと。Bに「おすすめ」 | H11: Bを選ぶと、困りごとの大きさと「流れが乱れたとき」という条件が分かりました。Aも必要な情報ですが、まだ困りごとの大きさは分かりません。Cは、お客様が判断できない状態で答えを出してしまっています。 | I11: 「流れが乱れたとき」という言葉、気になりませんか？ | J11: 「揺れているときに間違える？」 | K11: その気づきが原因を探す手がかりになる、と伝える。 | N11: 品質管理の高橋さんが、記録を見せてくれました。 | O11: 省略不可（判断理由の解説が学習の中心） | P11: 既存5・6・7
A12: S08 | B12: HEARING | C12: =E11 -> 8.75 | D12: 1.5 | E12: =C12+D12 -> 10.25 | F12: 講師 | G12: 週ごとの誤カウント率のグラフと、1万本あたりの表示本数（演習用の設定値） | H12: 1万本通ると、通常は50〜80本多く数えています。多い週だけ、300本ほど多くなりました。毎週ではありません。 | I12: 毎週同じではない、ということから何が言えそうですか？ | J12: 「いつもではなく、何かが起きたときに増える」 | K12: 「常に壊れているのではなく、条件で増える」という読み取りを評価する。 | L12: 「壊れているなら、毎週同じように増えるはず。では…？」 | N12: ここで、センサがどうやって数えているかを見ておきましょう。 | O12: 問いかけを省いて30秒に短縮可 | P12: 既存8
A13: S09 | B13: HEARING | C13: =E12 -> 10.25 | D13: 1 | E13: =C13+D13 -> 11.25 | F13: 講師 | G13: 3つの用語を身近な例で。右に回帰反射型の図 | H13: 自転車の後ろについている反射板は、車のライトを来た方向へ送り返しますよね。回帰反射型も同じで、センサの光を反射板が送り返します。ボトルが通ると戻る光が変わるので、「1本来た」と分かります。 | M13: IMAGE_PLACEHOLDER_02（既設の回帰反射型センサ） | N13: 次の質問を選んでください。 | O13: 時間がないときは「自転車の反射板」の一言だけにして30秒 | P13: 既存14（圧縮）
A14: S10 | B14: HEARING | C14: =E13 -> 11.25 | D14: 1.5 | E14: =C14+D14 -> 12.75 | F14: 個人→投票 | G14: 問いと3つの選択肢、考える時間30秒 | H14: 「流れが乱れたときに起こる気がする」という話を思い出して、選んでください。 | I14: 選んだ理由は？ | J14: A「実際に見ないと分からない」／B「予算がないと提案できない」／C「古いから壊れているかも」 | K14: Bの人には「予算は大事。ただ、今それを聞くとお客様はどう感じるか」を考えてもらう。 | L14: 森さん「『流れが乱れたとき』に起きるなら、どこを見れば手がかりがありそうですか？」 | N14: 聞いてみると… | O14: 理由の聞き取りを省けば1分 | P14: 既存9・10
A15: S11 | B15: HEARING | C15: =E14 -> 12.75 | D15: 1 | E15: =C15+D15 -> 13.75 | F15: 講師 | G15: 3つの選択肢それぞれの、お客様の答え。Aに「おすすめ」 | H15: 現場を見せてもらうと、センサがボトルの下のほうを横から見ていることが分かりました。Cの「故障の記録はない」も大事な事実です。壊れているのとは違う理由がありそうです。 | N15: ここまでで分かった事実を整理しましょう。 | O15: A以外の説明を一言にして30秒 | P15: 既存11・12・13
A16: S12 | B16: HEARING | C16: =E15 -> 13.75 | D16: 1.25 | E16: =C16+D16 -> 15 | F16: 講師 | G16: 確認できた事実5つと、まだ分からないこと1つ | H16: 事実が5つそろいました。でも、どこで、なぜ数が増えているのかは、まだ分かりません。ここからが「考える」時間です。 | M16: IMAGE_PLACEHOLDER_01（PETボトル搬送ライン） | N16: ANALYSISに進みます。 | O16: 読み上げずに見せるだけなら30秒 | P16: 新規（既存5〜13のまとめ）
A17: S13 | B17: ANALYSIS | C17: =E16 -> 15 | D17: 0.25 | E17: =C17+D17 -> 15.25 | F17: 講師 | G17: フェーズの扉 | H17: ここからは選択肢を減らします。自分で原因を考えてみてください。 | N17: まず、現場をよく見てみましょう。 | P17: 新規
A18: S14 | B18: ANALYSIS | C18: =E17 -> 15.25 | D18: 1.25 | E18: =C18+D18 -> 16.5 | F18: 動画 | G18: 映像②（30秒以内）→ 佐藤さんの一言 → 問い | H18: （映像のあと）佐藤さんが、ボトルが揺れたり、間隔が詰まったりする場所を教えてくれました。 | I18: 映像の中で、気になったことは何ですか？ | J18: 「ボトルが揺れていた」「くっついていた」「センサが低い位置にある」 | K18: 観察した事実をそのまま褒める。「なぜ数が増えるか」の答えはまだ言わない。 | L18: ボトル・センサ・ボトルの間、どこが動いていましたか？ | M18: VIDEO_PLACEHOLDER_02（映像② 現場の観察（揺れ・間隔の詰まり）） | N18: その前に、本数を数えるしくみを30秒で。 | O18: 問いを省いて映像だけなら45秒 | P18: 既存17・18
A19: S15 | B19: ANALYSIS | C19: =E18 -> 16.5 | D19: 1.25 | E19: =C19+D19 -> 17.75 | F19: 講師 | G19: センサ＝合図する係、PLC＝数える係。ボトル1本→合図1回→カウント+1の図 | H19: センサはボトルが来るたびに「来た！」と合図を出します。PLCはその合図の回数を数える装置です。だから、1本のボトルで合図が2回出ると、2本と数えてしまいます。これが「誤カウント」です。 | N19: では、1本なのに2本と数えてしまうのは、どんなときでしょう？ | O19: 省略不可（以降の理解の土台） | P19: 既存19（圧縮）
A20: S16 | B20: ANALYSIS | C20: =E19 -> 17.75 | D20: 2.5 | E20: =C20+D20 -> 20.25 | F20: 個人→ペア | G20: 自由記述の問い、時間配分、考える手がかり | H20: 選択肢はありません。思いついたことを、いくつでも書いてください。間違いはありません。 | I20: 1本のボトルを、2本と数えてしまうのはどんなとき？ | J20: 「ボトルが揺れて2回横切った」「2本がくっついた」「透明だから光がうまく当たらない」「センサが汚れている」「数える機械の設定」 | K20: 出た意見を「ボトル」「光とセンサ」「数える装置」の3つに分けて板書する。どれも「まだ仮説」と強調する。 | L20: 中田さん「数が増える場所は1つとは限りません。ボトル・センサ・数える装置、どこで起きていそう？」 | N20: 皆さんの仮説を整理すると、こうなります。 | O20: 共有を2人だけにすれば2分 | P20: 既存15・16（3択→自由記述）
A21: S17 | B21: ANALYSIS | C21: =E20 -> 20.25 | D21: 1.25 | E21: =C21+D21 -> 21.5 | F21: 講師 | G21: 3つの場所に5つの候補。すべて「仮説」と表示 | H21: 皆さんの意見を整理すると、5つの候補になります。大事なのは、どれもまだ「候補」で、原因は決まっていないことです。たとえば「ボトルの接近」は、くっつくと逆に少なく数えることもあるので、本当に増える原因かは確かめないと分かりません。 | K21: 学生の意見と対応するものを指さしながら説明する。 | N21: それぞれ、分かっていることと、まだ分からないことを分けてみます。 | O21: 読み上げを候補名だけにすれば45秒 | P21: 既存17〜20・26
A22: S18 | B22: ANALYSIS | C22: =E21 -> 21.5 | D22: 1.5 | E22: =C22+D22 -> 23 | F22: 講師 | G22: 5つの候補を「確認できた事実／考えられる仮説／次に必要な検証」の3列で整理 | H22: 左が確認できた事実、真ん中が仮説、右が次に確かめることです。「お客様が気がしている」は印象なので、まだ事実ではありません。こうして分けると、何を確かめればいいかが見えてきます。 | N22: 透明ボトルの仮説を、イメージで見てみましょう。 | O22: 1行目（揺れ）だけ説明し、残りは見せるだけなら45秒 | P22: 既存17〜20・24・26
A23: S19 | B23: ANALYSIS | C23: =E22 -> 23 | D23: 1.25 | E23: =C23+D23 -> 24.25 | F23: 講師 | G23: ボトル1本が通るあいだの合図。左：通常（1回）、右：仮説（2回）。「仮説検証用のイメージ（実測ではありません）」と明記 | H23: これは研修用のイメージで、実際に測ったものではありません。ボトル1本なのに、合図が途中で一度途切れると、PLCは2本と数えます。透明なボトルは光の減り方が小さいので、こうしたことが起きやすいと言われています。ただし、このお客様のラインで本当に起きているかは、まだ分かりません。 | M23: IMAGE_PLACEHOLDER_03（PETボトルの誤検出） | N23: では、どうやって確かめますか？ | O23: 省略可（S17の説明で代える）。ただし映像化した場合は残す | P23: 既存20
A24: S20 | B24: ANALYSIS | C24: =E23 -> 24.25 | D24: 1.25 | E24: =C24+D24 -> 25.5 | F24: 個人→投票 | G24: 問いと3つの選択肢、考える時間30秒 | H24: 原因の候補は5つ。どこで数が増えているかを知るには、どうすればいいでしょう。 | I24: 選んだ理由は？ | J24: A「早く直したい」／B「どこで増えるか分かる」／C「遅くすれば安定しそう」 | K24: Cの人には「速度を下げると、お客様にとって何が困る？」と問い返す。 | L24: 中田さん「『どこで数が増えているか』が分かる方法は、どれでしょう？」 | N24: 答えを見てみましょう。 | O24: 理由の聞き取りを省けば45秒 | P24: 既存21・22
A25: S21 | B25: ANALYSIS | C25: =E24 -> 25.5 | D25: 1.75 | E25: =C25+D25 -> 27.25 | F25: 講師 | G25: 通過本数・合図の回数・PLCのカウントを同時に記録し、どちら側で増えているかを分ける図。A・Cへのお客様の反応 | H25: 同じ時間に3つを記録します。合図の回数が本数より多ければ、センサ側、つまりボトルや光や設置で増えています。合図の回数は合っているのにカウントが多ければ、PLC側の数え方です。こうして場所を分けると、候補を絞り込めます。 | I25: AとCを選ぶと、お客様はどう感じたでしょう？ | J25: 「直らなかったら困る」「生産が減るのは困る」 | K25: お客様の反応は、あとで提案を考えるときの大事な条件になる、と伝えておく（S30で使う）。 | N25: ここで、今日いちばん大事な問いです。 | O25: A・Cの反応を読み上げなければ1分 | P25: 既存23・24・25
A26: S22 | B26: ANALYSIS | C26: =E25 -> 27.25 | D26: 2 | E26: =C26+D26 -> 29.25 | F26: グループ | G26: 自由記述の問いと時間配分 | H26: ここまでの体験を使って考えてください。営業がお客様に信頼されるために、いちばん大事な考え方です。 | I26: 原因を決めつけずに調べるには、何を確認すればよいでしょうか？ | J26: 「いろいろな場所を同時に記録する」「条件を変えて試す」「多い日と少ない日を比べる」「お客様にもっと聞く」 | K26: 出た意見を次のスライドの3つに対応づけて認める。「お客様にもっと聞く」はHEARINGの大切さとして評価する。 | L26: 「揺れのせいだ」と言い切るには、どんな比べ方をすればいい？ | N26: 皆さんの答えをまとめると… | O26: 発表を省き、講師がまとめるなら1分30秒 | P26: 新規
A27: S23 | B27: ANALYSIS | C27: =E26 -> 29.25 | D27: 0.75 | E27: =C27+D27 -> 30 | F27: 講師 | G27: 確かめ方3つと、まとめのメッセージ | H27: 事実と仮説を分けて、確かめてから判断する。これがコンサルティング営業の考え方の核です。決めつけないから、お客様は納得して判断できます。 | N27: ここで少し、お客様の気持ちに目を向けてみましょう。 | P27: 新規（既存26を発展）
A28: S24 | B28: DISCOVERY | C28: =E27 -> 30 | D28: 0.25 | E28: =C28+D28 -> 30.25 | F28: 講師 | G28: フェーズの扉 | H28: ここが今日の中心です。お客様が本当に困っていることを、皆さん自身で見つけてください。 | P28: 新規
A29: S25 | B29: DISCOVERY | C29: =E28 -> 30.25 | D29: 1.5 | E29: =C29+D29 -> 31.75 | F29: 個人 | G29: 佐藤さん・高橋さんの言葉と、自由記述の問い（30秒） | H29: 「何とか対応できている」。この言葉、そのまま受け取っていいでしょうか。 | I29: この言葉の裏に、何がありそうですか？次に、何を聞きますか？ | J29: 「本当は大変なのでは？」「誰かが手で数え直している？」「どれくらい手間がかかっているか聞く」 | K29: 「何とか」という言葉に引っかかった人を評価する。価格や他社事例を聞くという答えには、聞いた場合の反応を次のスライドで見せる。 | L29: 森さん「『何とか対応できている』の裏に、困りごとが隠れていそうです」 | M29: IMAGE_PLACEHOLDER_06（お客様（佐藤さん・高橋さん）の人物） | N29: 聞いてみると… | O29: 考える時間を15秒にすれば1分 | P29: 既存27・28・29（3択→自由）
A30: S26 | B30: DISCOVERY | C30: =E29 -> 31.75 | D30: 1.25 | E30: =C30+D30 -> 33 | F30: 講師 | G30: 手間を聞いたときの答えと、価格・他社事例を聞いたときの答え | H30: 手間を聞くと、確認のし直しや、ライン停止まで起きていることが分かりました。価格や他社事例を聞くと、お客様は「それより、うちの原因を知りたい」と答えています。 | N30: では、今日の中心の問いです。 | O30: 右側（価格・他社事例）を省けば45秒 | P30: 既存30・31・32
A31: S27 | B31: DISCOVERY | C31: =E30 -> 33 | D31: 3 | E31: =C31+D31 -> 36 | F31: 個人→グループ | G31: 自由記述の問いと時間配分。答えは表示しない | H31: 誤カウントがなくなったら、お客様は何がうれしいのか。数が合うこと、のさらに先を考えてみてください。 | I31: 誤カウントがなくなると、お客様は何がうれしいのでしょうか？ | J31: 「確認作業がなくなる」「ラインを止めなくていい」「品質管理の人が楽になる」「安心して生産できる」「上司に報告しなくていい」 | K31: 「数が合う」で止まったグループには「数が合うと、誰の何が楽になる？」と問い返す。答えを先に言わない。 | L31: 「確認し直す」「ラインを止める」。それがなくなると、工場はどうなる？ | N31: 皆さんの答えを、3つの段に整理してみます。 | O31: 省略不可（プログラムの中心）。発表を1グループにすれば2分30秒 | P31: 既存33・34（3択→自由記述）
A32: S28 | B32: DISCOVERY | C32: =E31 -> 36 | D32: 1.25 | E32: =C32+D32 -> 37.25 | F32: 講師 | G32: 3段の構造。1段目「表面の問題」、2段目「業務への影響」を表示し、3段目は「？」で伏せる | H32: 1段目は、ボトルを実際より多く数えてしまうこと。2段目は、そのせいで確認し直しやライン停止が起き、品質管理の負担が増えていること。では3段目、お客様が本当に実現したいことは何でしょう？皆さんの答えの中にありました。 | I32: 3段目に入る言葉は何でしょう？ | J32: 「安心して生産したい」「止まらないラインにしたい」 | K32: 学生の言葉を使って3段目を言ってもらう。言えたら次のスライドで答え合わせ。 | L32: 佐藤さんは、価格より何が大事だと言っていましたか？ | N32: 佐藤さんに聞いてみましょう。 | P32: 既存36〜38
A33: S29 | B33: DISCOVERY | C33: =E32 -> 37.25 | D33: 1.5 | E33: =C33+D33 -> 38.75 | F33: 講師 | G33: 3段目「安定した生産を続けたい」を表示し、佐藤さんの言葉 | H33: お客様が本当に実現したいのは、「安定した生産を続けること」でした。目の前の問題と、お客様が本当に実現したいことは違う。ここに気づけるかどうかが、営業の腕の見せどころです。 | I33: 自分たちの答えと比べて、どうでしたか？ | J33: 「近かった」「数が合えばいいと思っていた」 | K33: 近い答えを出したグループを名指しで褒める。 | N33: これを、提案の判断基準として整理します。 | P33: 既存36・37
A34: S30 | B34: DISCOVERY | C34: =E33 -> 38.75 | D34: 1.25 | E34: =C34+D34 -> 40 | F34: 講師 | G34: お客様の要求3つと、それぞれの出どころ | H34: この3つが、これから提案するときの判断基準です。3つ目の「生産を止めずに」は、速度を下げる案や、交換するだけの案を出したときのお客様の反応から分かったことです。断られた選択肢にも、大事な情報が入っています。 | N34: いよいよ提案です。 | P34: 既存38・25・44
A35: S31 | B35: PROPOSAL | C35: =E34 -> 40 | D35: 0.25 | E35: =C35+D35 -> 40.25 | F35: 講師 | G35: フェーズの扉 | H35: 最後は、皆さん自身の言葉で、お客様に提案してもらいます。 | P35: 新規
A36: S32 | B36: PROPOSAL | C36: =E35 -> 40.25 | D36: 0.5 | E36: =C36+D36 -> 40.75 | F36: 講師 | G36: 6ステップ。1〜3は完了済み | H36: 1から3は、ここまでで皆さんがやってきたことです。残りは、候補の技術を紹介し、確かめ方を決めて、お客様と合意することです。 | N36: 提案の候補は、OPTEX-FAのこのセンサです。 | O36: 見せるだけなら15秒 | P36: 既存39
A37: S33 | B37: PROPOSAL | C37: =E36 -> 40.75 | D37: 1 | E37: =C37+D37 -> 41.75 | F37: 講師 | G37: KR-Qシリーズの確認済みの情報3つと、提案の考え方。仕様の数値は載せない | H37: OPTEX-FAには、透明な物の検出に向けたKR-Qシリーズがあります。方式は今のセンサと同じ回帰反射型です。ただし、「これに替えれば必ず直る」とは言いません。お客様のボトルとラインで確かめることが大切です。 | M37: IMAGE_PLACEHOLDER_04（OPTEX-FA製品・検出原理） VIDEO_PLACEHOLDER_03（映像③ 検出原理（既設とKR-Qシリーズ）） | N37: どうやって確かめるかも決めておきましょう。 | O37: 仕様の説明はしない（公式資料の照合前のため） | P37: 既存39・45
A38: S34 | B38: PROPOSAL | C38: =E37 -> 41.75 | D38: 0.75 | E38: =C38+D38 -> 42.5 | F38: 講師 | G38: 同じにする条件・変える条件・記録すること・合格の基準（試す前に決める）。左に設置図 | H38: 既設のセンサとKR-Qシリーズを、同じ条件で比べます。大事なのは、合格の基準を試す前にお客様と決めておくことです。後から基準を変えると、お客様は結果を信じられません。 | I38: デモで確認すべきことは、センサの見た目でしょうか、それとも？ | J38: 「本数とカウントが合うか」 | K38: 「お客様が困っていたのは何だったか」に戻って考えた人を評価する。 | L38: 中田さん「お客様が困っていたのは、何でしたか？」 | M38: IMAGE_PLACEHOLDER_07（比較検証の設置図） | N38: 材料はそろいました。皆さんの提案をつくりましょう。 | O38: 問いかけを省けば30秒 | P38: 既存46〜52・65〜68
A39: S35 | B39: PROPOSAL | C39: =E38 -> 42.5 | D39: 5 | E39: =C39+D39 -> 47.5 | F39: 個人→グループ | G39: 3つの問い、提案の型（穴埋め）、時間配分 | H39: 提案の型を使って構いません。製品の説明ではなく、お客様が「それならやってみたい」と思える提案を目指してください。発表は1グループ90秒です。 | I39: 3つの問いに答えて、提案をまとめてください。 | J39: 「困っているのは確認とライン停止の負担。KR-Qシリーズを提案。透明なボトル向けだから。まず実際のボトルで比べたい」 | K39: 机間巡視で「次に何を確認するか」が抜けているグループに声をかける。 | L39: S30の3つの要求と、S34の検証計画を見返してみましょう。 | N39: では、お客様に提案してみましょう。 | O39: 指示書の推奨は「考える3分＋まとめる4分」。時間に余裕があれば7分に延ばす | P39: 既存40・41（3択→模擬提案）
A40: S36 | B40: PROPOSAL | C40: =E39 -> 47.5 | D40: 4 | E40: =C40+D40 -> 51.5 | F40: グループ発表 | G40: 発表のルールと、お客様役が聞いているポイント3つ | H40: お客様役は、佐藤さん・高橋さん役の社員です。お客様役は、この3つのポイントで聞いています。 | I40: （お客様役）発表を聞いて、お客様として率直に反応する。 | J40: 「すぐ交換しましょう」型の提案も出る | K40: 3つのポイントで1つずつ良い点を伝え、足りない点は「お客様としては、ここが知りたい」と質問の形で返す。正解かどうかでは評価しない。「交換しましょう」型には「交換して直らなかったら…」と、お客様の不安を返す。 | L40: 詰まったら、提案の型の1行目だけ読んでもらう。 | N40: 皆さんの提案を聞いた佐藤さんの反応です。 | O40: 標準2グループ（3分＋反応1分）。3グループなら+2分、ほかの省略候補で調整 | P40: 新規
...

Sheet 2_全体構成
A1: 成果物② 新しい全体構成（60分）
A2: 時間は「4_講師用進行台本」の所要時間から自動計算。学生の行動を「選ぶ→考える→発見する→提案する→顧客の反応を得る」へ段階的に変える
A4: フェーズ | B4: 日本語 | C4: 予定（分） | D4: 開始 | E4: 終了 | F4: 台本上の所要（分） | G4: 差 | H4: スライド | I4: 学生がすること | J4: 参加型ワーク
A5: MISSION | B5: ミッション | C5: 5 | D5: 0 | E5: 5 | F5: =SUMIF(4_講師用進行台本!$B$5:$B$49,A5,4_講師用進行台本!$D$5:$D$49) -> 5 | G5: =F5-C5 -> 0 | H5: S01〜S04（4枚） | I5: お客様からのSOSと、あなたのミッション | J5: 事前チェック（S02）
A6: HEARING | B6: 聞く | C6: 10 | D6: 5 | E6: 15 | F6: =SUMIF(4_講師用進行台本!$B$5:$B$49,A6,4_講師用進行台本!$D$5:$D$49) -> 10 | G6: =F6-C6 -> 0 | H6: S05〜S12（8枚） | I6: 質問して、困りごとを具体的にする | J6: 3択×2（S06・S10）。考える30秒＋理由を聞く
A7: ANALYSIS | B7: 考える | C7: 15 | D7: 15 | E7: 30 | F7: =SUMIF(4_講師用進行台本!$B$5:$B$49,A7,4_講師用進行台本!$D$5:$D$49) -> 15 | G7: =F7-C7 -> 0 | H7: S13〜S23（11枚） | I7: 原因の仮説を立て、確かめ方を考える | J7: 自由記述：仮説を立てる（S16）／3択（S20）／グループ：原因を決めつけずに調べるには？（S22）
A8: DISCOVERY | B8: 発見する | C8: 10 | D8: 30 | E8: 40 | F8: =SUMIF(4_講師用進行台本!$B$5:$B$49,A8,4_講師用進行台本!$D$5:$D$49) -> 10 | G8: =F8-C8 -> 0 | H8: S24〜S30（7枚） | I8: お客様が本当に実現したいことを見つける | J8: 自由記述：この一言の裏は？（S25）／中心ワーク：誤カウントがなくなると何がうれしい？（S27）／3段目を言葉にする（S28）
A9: PROPOSAL | B9: 提案する | C9: 13 | D9: 40 | E9: 53 | F9: =SUMIF(4_講師用進行台本!$B$5:$B$49,A9,4_講師用進行台本!$D$5:$D$49) -> 13 | G9: =F9-C9 -> 0 | H9: S31〜S38（8枚） | I9: 自分の言葉で提案し、お客様の反応を得る | J9: 模擬提案ワーク（S35：考える2分＋まとめる3分）／提案タイム（S36：90秒×2組＋顧客役の反応）
A10: REFLECTION | B10: ふりかえる | C10: 7 | D10: 53 | E10: 60 | F10: =SUMIF(4_講師用進行台本!$B$5:$B$49,A10,4_講師用進行台本!$D$5:$D$49) -> 7 | G10: =F10-C10 -> 0 | H10: S39〜S45（7枚） | I10: 営業の仕事の面白さを言葉にする | J10: ペアで振り返り（S41）／事後アンケート（S45）
A11: 合計 | C11: =SUM(C5:C10) -> 60 | F11: =SUM(F5:F10) -> 60 | G11: =SUM(G5:G10) -> 0 | H11: =COUNTA(4_講師用進行台本!A5:A49)&"枚" -> 45枚
A13: ・時間の内訳（目安）：動画 約3分／学生が考える・話す・発表する 約22分／講師の説明 約35分
A14: ・PROPOSALの模擬提案ワークは、指示書の推奨（3分＋4分＋4分＋2分）より短い「考える2分＋まとめる3分＋発表と反応4分」。理由と代案は「8_要確認事項」
A15: ・時間を超えそうなときの削り方：S19（仮説のイメージ）→ S44（若手社員：素材がないうちは非表示）→ S26右側 → S09を一言に。合計で約5〜7分短くできる
A16: ・発表の組数を増やすとき：1組増えるごとに約2分。上の削り方で時間をつくる

Sheet 5_画像動画差し替え管理
A1: 成果物⑤ 画像・動画差し替え管理表
A2: スライド上の枠は、PowerPointの「選択ウィンドウ」で同じ番号の名前がついている。枠の比率に合わせて用意すると、余白なく収まる
A4: 番号 | B4: 種類 | C4: 用途 | D4: 配置フェーズ | E4: スライド | F4: 目的 | G4: 枠の大きさ（インチ） | H4: 枠の比率 | I4: 推奨の大きさ（px） | J4: 仮素材 | K4: 長さの上限 | L4: 状況 | M4: 差し替え予定日 | N4: 担当 | O4: 備考
A5: IMAGE_PLACEHOLDER_01 | B5: 画像 | C5: PETボトル搬送ライン | D5: MISSION・HEARING | E5: S01 | F5: 工場の現場状況を直感的に理解させる | G5: 4.4×2.5 | H5: 16:9 | I5: 1320×750以上 | J5: 既存の導入動画・オープニング映像の静止画 | L5: 仮画像を配置
A6: IMAGE_PLACEHOLDER_09 | B6: 画像 | C6: 事前チェックのQRコード | D6: MISSION | E6: S02 | F6: 参加前の興味を回答してもらう | G6: 3.2×3.2 | H6: 1:1 | I6: 960×960以上 | J6: なし（点線の枠のみ） | L6: 未提供
A7: VIDEO_PLACEHOLDER_01 | B7: 動画 | C7: 映像① 課題発生 | D7: MISSION | E7: S04 | F7: ラインで、実際の本数より多く数えられる状況を見せる | G7: 7.4×4.16 | H7: 16:9 | I7: 2220×1248以上 | J7: 既存の導入動画（3分58秒）。60秒以内に編集して使う | K7: 60秒以内 | L7: 仮画像を配置
A8: IMAGE_PLACEHOLDER_02 | B8: 画像 | C8: 既設の回帰反射型センサ | D8: HEARING・ANALYSIS | E8: S09 | F8: 光の通り方とボトルの関係を説明する | G8: 5.18×4.65 | H8: 1.11:1 | I8: 1554×1395以上 | J8: 既存の導入動画「回帰反射型」の図 | L8: 仮画像を配置
A9: IMAGE_PLACEHOLDER_01 | B9: 画像 | C9: PETボトル搬送ライン | D9: MISSION・HEARING | E9: S12 | F9: 工場の現場状況を直感的に理解させる | G9: 4.78×2.69 | H9: 16:9 | I9: 1434×807以上 | J9: 既存の導入動画・オープニング映像の静止画 | L9: 仮画像を配置
A10: VIDEO_PLACEHOLDER_02 | B10: 動画 | C10: 映像② 現場の観察（揺れ・間隔の詰まり） | D10: ANALYSIS | E10: S14 | F10: 原因の候補を、答えを言わずに観察させる | G10: 7.4×4.16 | H10: 16:9 | I10: 2220×1248以上 | J10: 既存クリップ p1-q2-a・p2-q1-a（ラインの様子） | K10: 30秒以内 | L10: 仮画像を配置
A11: IMAGE_PLACEHOLDER_03 | B11: 画像 | C11: PETボトルの誤検出 | D11: ANALYSIS | E11: S19 | F11: 誤カウントが発生する様子を可視化する（仮説のイメージ） | G11: 3.6×3.96 | H11: 0.91:1 | I11: 1080×1188以上 | J11: 既存スライド20の図（ボトル下部の検出位置） | L11: 仮画像を配置
A12: IMAGE_PLACEHOLDER_06 | B12: 画像 | C12: お客様（佐藤さん・高橋さん）の人物 | D12: DISCOVERY | E12: S25 | F12: 「何とか対応できている」と話すお客様の表情を見せる | G12: 3.3×3.4 | H12: 1:1 | I12: 990×1020以上 | J12: なし（点線の枠のみ） | L12: 未提供
A13: IMAGE_PLACEHOLDER_04 | B13: 画像 | C13: OPTEX-FA製品・検出原理 | D13: PROPOSAL | E13: S33 | F13: 既設センサとの違いを視覚的に説明する | G13: 4.4×2.9 | H13: 1.52:1 | I13: 1320×870以上 | J13: なし（点線の枠のみ） | L13: 未提供
A14: VIDEO_PLACEHOLDER_03 | B14: 動画 | C14: 映像③ 検出原理（既設とKR-Qシリーズ） | D14: PROPOSAL | E14: S33 | F14: 確認済みの技術情報だけで、検出のしくみを比べる | G14: 4.4×1.85 | H14: 2.38:1 | I14: 1320×555以上 | J14: なし（点線の枠のみ） | K14: 45秒以内 | L14: 未提供
A15: IMAGE_PLACEHOLDER_07 | B15: 画像 | C15: 比較検証の設置図 | D15: PROPOSAL | E15: S34 | F15: 同じ条件で2つのセンサを比べる配置を示す | G15: 4.2×4.53 | H15: 0.93:1 | I15: 1260×1359以上 | J15: 既存スライド46の設置図 | L15: 仮画像を配置
A16: VIDEO_PLACEHOLDER_04 | B16: 動画 | C16: 映像④ 顧客との対話（反応） | D16: PROPOSAL | E16: S37 | F16: 学生の提案のあとに、お客様の気持ちが動く場面を見せる | G16: 4.6×2.6 | H16: 16:9 | I16: 1380×780以上 | J16: なし（点線の枠のみ） | K16: 30秒以内 | L16: 未提供
A17: IMAGE_PLACEHOLDER_05 | B17: 画像 | C17: 顧客と営業担当者の対話 | D17: PROPOSAL・REFLECTION | E17: S37 | F17: 顧客の信頼獲得と営業の面白さを表現する | G17: 4.6×2.1 | H17: 2.19:1 | I17: 1380×630以上 | J17: なし（点線の枠のみ） | L17: 未提供
A18: IMAGE_PLACEHOLDER_05 | B18: 画像 | C18: 顧客と営業担当者の対話 | D18: PROPOSAL・REFLECTION | E18: S42 | F18: 顧客の信頼獲得と営業の面白さを表現する | G18: 4.2×1.65 | H18: 2.55:1 | I18: 1260×495以上 | J18: なし（点線の枠のみ） | L18: 未提供
A19: IMAGE_PLACEHOLDER_08 | B19: 画像 | C19: 若手営業社員の写真 | D19: REFLECTION | E19: S44 | F19: 学生が「自分もなれそう」と感じる実在の先輩を見せる | G19: 3.6×4.5 | H19: 3:4 | I19: 1080×1350以上 | J19: なし（点線の枠のみ） | L19: 未提供
A20: VIDEO_PLACEHOLDER_05 | B20: 動画 | C20: 若手営業社員のメッセージ（任意） | D20: REFLECTION | E20: S44 | F20: 入社後の姿を具体的に想像させる | G20: 4.2×2.36 | H20: 16:9 | I20: 1260×708以上 | J20: なし（点線の枠のみ） | K20: 60秒以内 | L20: 未提供
A21: IMAGE_PLACEHOLDER_10 | B21: 画像 | C21: 事後アンケート・次回ステップ申込のQRコード | D21: REFLECTION | E21: S45 | F21: 体験直後に回答と申込をしてもらう | G21: 3.2×3.2 | H21: 1:1 | I21: 960×960以上 | J21: なし（点線の枠のみ） | L21: 未提供
A22: IMAGE_PLACEHOLDER_11 | B22: 画像 | C22: 比較デモの4条件（通常・揺れ・間隔・高さ） | D22: 補足資料 | E22: X04 | F22: 検証で変える条件を説明する | G22: 2.85×2.18 | H22: 4:3 | I22: 855×654以上 | J22: 既存スライド65〜68の図（「間隔の変化」は描き直しが必要） | L22: 仮画像を配置
A24: 差し替えのルール（指示書14章）
A25: 1. 指定画像を最優先し、仮画像を置き換える。被写体・形状・重要なディテールは加工しない
A26: 2. 縦横比を保つ（引き伸ばさない）。比率が枠と違うときは、枠の中に収めて余白を背景色で埋める
A27: 3. 背景透過画像は透明部分を保つ
A28: 4. 既存デザインとの統一感は、背景・余白・文字配置で調整する
A29: 5. 動画は「長さの上限」以内。上限を超える場合は「4_講師用進行台本」の所要時間を見直す
A30: 6. 追加の画像・動画は IMAGE_PLACEHOLDER_12／VIDEO_PLACEHOLDER_06 から連番で、この表に行を足す
A32: 状況ごとの件数
A33: 未提供 | B33: =COUNTIF($L$5:$L$22,A33) -> 10
A34: 仮画像を配置 | B34: =COUNTIF($L$5:$L$22,A34) -> 8
A35: 素材受領 | B35: =COUNTIF($L$5:$L$22,A35) -> 0
A36: 差し替え済み | B36: =COUNTIF($L$5:$L$22,A36) -> 0
A37: 確認済み | B37: =COUNTIF($L$5:$L$22,A37) -> 0

Sheet 6_品質確認
A1: 成果物⑥ 品質確認
A2: ○＝満たす △＝条件付き・素材待ち
A4: 確認項目 | B4: 確認した内容 | C4: 判定 | D4: 残る課題・前提
A5: 60分以内に終了するか | B5: 本編45枚の所要時間の合計は60分（各フェーズの時間枠と一致）。ただし余裕はない。「省略候補」を使うと最大約7分短縮できる | C5: △（余裕なし） | D5: 講師台本の「時間超過時の調整」列。当日はS19・S44・S26右側・S09から削る
A6: 学生が自ら考える場面があるか | B6: 3択3回（S06・S10・S20）→ 自由記述4回（S16・S22・S25・S27）→ 模擬提案（S35・S36）→ ふりかえり（S41）。学生が手を動かす時間は約22分 | C6: ○ | D6: 後半ほど自由度が上がる（選ぶ→考える→発見する→提案する）
A7: 顧客の真の課題が理解できるか | B7: S25〜S30の6枚・10分を中心に配置。答え（安定した生産）は学生が考えたあと（S29）に初めて表示 | C7: ○ | D7: 導入動画に答えが先に出る場面があるため、編集が必要（要確認事項）
A8: 技術的な説明に矛盾がないか | B8: 原因はすべて「候補（仮説）」と表示。「接近」は少なく数える方向にも働くことを明記。シミュレーションは「仮説検証用のイメージ」と明記。製品の数値は載せていない | C8: ○（条件付き） | D8: 既存スライド67の重なった描写は補足に移し、修正が必要と明記。製品情報は公式ページでの照合が残る
A9: 提案までの論理が成立しているか | B9: 顧客要求（S30）→ 6ステップ（S32）→ 候補（S33）→ 検証計画と合格基準（S34）→ 提案（S35・S36）→ 合意（S38）。「他社製だから」「必ず解決」の表現なし | C9: ○
A10: 営業の達成感を得られるか | B10: 学生の発表（S36）のあとに、お客様の前向きな反応（S37）と「次の一歩を任される」場面（S38）を置いた | C10: ○ | D10: 顧客役の社員が、学生の提案の良い点を具体的に返すことが前提
A11: 採用への接続が自然か | B11: メッセージ（S42）→ 営業の魅力（S43）→ 若手社員（S44）→ 次のステップ（S45）。前後の興味の変化を測る | C11: △（素材待ち） | D11: 育成制度・若手社員・申込URLが未提供
A12: 後からイラスト・動画を追加できるか | B12: 画像11枠・動画5枠に管理番号をつけ、PowerPointの「選択ウィンドウ」で同じ名前のオブジェクトを選べるようにした。仮画像は既存動画の切り出しで、比率を変えずに配置 | C12: ○ | D12: 差し替え管理表に、枠の大きさと比率を記載
A14: 技術面で直した・明記した点
A15: ・「ボトルの接近」は、ボトルがくっつくと区切りがなくなり、むしろ少なく数える方向に働く。増える原因かは要確認と明記した（S17・S18）
A16: ・既存スライド67（間隔の変化）は、上から見た図でボトル同士が重なって描かれており、実際には起きない。本編から外し、補足X04で修正が必要と明記
A17: ・KR-Qシリーズは、既設と同じ「回帰反射型」。違いは「透明体の検出に向けて設計されていること」とだけ表現し、性能の数値・他社との優劣は載せていない
A18: ・既存の導入動画は、0:15〜1:35付近で「お客様が実現したいこと」「確認作業が増える→生産効率が下がる」を先に見せている。DISCOVERYの答えが先に見えるため、使う範囲を限定する
A19: ・現状データ（＋0.5〜0.8％、最大＋3.0％、10,050〜10,080本／10,300本）は、1万本に対する計算と一致。スライドに「演習用の設定値」と明記

Sheet 7_アンケート
A1: 成果物⑦ 成果測定（アンケート）
A2: 事前（S02）と事後（S45）で同じ問いを聞き、変化を見る。採用成果は次回ステップへの参加率で確認する
A4: 設問 | B4: 事前チェック（開始時・1分） | C4: 回答形式
A5: Q0-1 | B5: 営業の仕事に、どれくらい興味がありますか？ | C5: 5段階（1 まったくない〜5 とてもある）
A6: Q0-2 | B6: 営業とは、どんな仕事だと思いますか？ | C6: 自由記述（ひとこと）
A8: 設問 | B8: 事後アンケート（終了時・2分） | C8: 回答形式
A9: Q1 | B9: 営業の仕事内容を理解できましたか？ | C9: 5段階
A10: Q2 | B10: 課題を発見する体験は面白かったですか？ | C10: 5段階
A11: Q3 | B11: 自分でも営業の仕事に挑戦できそうだと感じましたか？ | C11: 5段階
A12: Q4 | B12: 参加前と比べて、OPTEX-FAへの興味は高まりましたか？ | C12: 5段階（1 下がった〜3 変わらない〜5 とても高まった）
A13: Q5 | B13: もっと詳しく知りたい内容は何ですか？ | C13: 複数選択（仕事内容／製品・技術／育成・研修／働き方／社員）＋自由記述
A14: Q6 | B14: 次の会社説明・社員交流・選考に参加したいですか？ | C14: 選択（ぜひ参加したい／日程が合えば／今は考えていない）
A15: Q7 | B15: 営業の仕事に、どれくらい興味がありますか？（事前と同じ問い） | C15: 5段階。事前Q0-1との差で変化を見る
A16: Q8 | B16: 営業とは、どんな仕事だと思いますか？（事前と同じ問い） | C16: 自由記述。事前Q0-2と比べる
... A22: 次回ステップ参加率（採用成果） | B22: 次のステップに実際に参加した人数 ÷ 体験の参加人数 | C22: 要設定（人事の申込データと照合）

Sheet 8_要確認事項
A1: 要確認事項
A2: 推測で事実を補わず、確認が必要なものとして残した事項
A4: No | B4: 分類 | C4: 内容 | D4: 関係するスライド・素材 | E4: 確認先（案） | F4: 回答・決定事項 | G4: 状況
A5: 1 | B5: 製品情報 | C5: KR-Qシリーズの仕様・特長を公式ページで直接照合する（この環境から公式サイトに接続できず、検索抜粋のみで確認） | D5: S33・X06 | E5: 営業企画／技術 | G5: 未確認
A6: 2 | B6: 製品情報 | C6: KR-Qシリーズの光源の表記（公式抜粋：赤色LED／販売店：赤外LED）の食い違い | D6: X06 | E6: 技術 | G6: 未確認
A7: 3 | B7: 製品情報 | C7: 「屈折光除去機能」など公式の特長表現を教材に使ってよいか（現在は載せていない） | D7: S33 | E7: 技術・広報 | G7: 未確認
A8: 4 | B8: 画像 | C8: 製品画像・ロゴを使う場合の利用許諾（OPTEX-FA公式サイトの二次利用は事前許諾が必要） | D8: IMAGE_PLACEHOLDER_04 | E8: 広報 | G8: 未確認
A9: 5 | B9: 採用 | C9: OPTEX-FAの育成制度・営業の業務内容（S43の具体例） | D9: S43 | E9: 人事 | G9: 未確認
A10: 6 | B10: 採用 | C10: 若手営業社員の写真・入社年・担当・メッセージ | D10: S44 | E10: 人事 | G10: 未確認
A11: 7 | B11: 採用 | C11: 事前チェック・事後アンケートの回答フォームとQRコード、次のステップの日程と申込URL | D11: S02・S45 | E11: 人事 | G11: 未確認
A12: 8 | B12: 運営 | C12: 顧客役（佐藤さん・高橋さん役）を演じる社員2名と、事前の打ち合わせ | D12: S36 | E12: 営業企画 | G12: 未確認
A13: 9 | B13: 運営 | C13: 参加人数とグループ数（発表できる組数が決まる。標準は2組） | D13: S36 | E13: 人事 | G13: 未確認
A14: 10 | B14: 運営 | C14: 3択の回答方法（既存のスマホ投票アプリ／挙手） | D14: S06・S10・S20 | E14: 営業企画 | G14: 未確認
A15: 11 | B15: 映像 | C15: 既存の導入動画（3分58秒）を60秒以内に編集する。0:15〜1:35付近は「お客様が実現したいこと」「確認作業が増える」を先に見せてしまうため、DISCOVERYの答えが先に見える | D15: VIDEO_PLACEHOLDER_01 | E15: 制作 | G15: 未確認
A16: 12 | B16: 映像 | C16: 映像④の新しい台詞（演習用）の音声収録 | D16: VIDEO_PLACEHOLDER_04 | E16: 制作 | G16: 未確認
... A18: 14 | B18: 時間 | C18: PROPOSALの模擬提案ワークは、指示書の推奨（3分＋4分＋4分＋2分＝13分）だとフェーズ全体の13分を使い切り、KR-Qの紹介や合意の場面が入らない。本案は「考える2分＋まとめる3分＋発表と反応4分」に短縮。推奨どおりにする場合は、全体を65分にするか、ANALYSISを3分短くする | D18: S35・S36 | E18: 営業企画（判断） | G18: 未確認
